Workbook

Sheet Mode d'emploi
A1: TNR - Parcours UX/UI
A2: Campagne de non-regression a rejouer avant chaque mise en production.
A5: Perimetre | B5: Page de suivi deployee sur Vercel : index.html, parcours.json, api/progress.js.
A6: Quand la rejouer | B6: Avant toute mise en production : modification du contenu, du gabarit, de la fonction serveur ou du stockage.
A7: Duree indicative | B7: Passe complete : environ 2 h. Passe courte (cas P1 seuls) : environ 45 min.
A9: COMMENT REMPLIR
A10: Onglet a remplir | B10: Cas de test uniquement. Les colonnes Mobile, Tablette, Desktop et Anomalie sont les seules cellules a saisir.
A11: Valeurs autorisees | B11: OK - KO - N/A - Non teste (liste deroulante dans chaque cellule)
A12: N/A pre-rempli | B12: Les cellules grisees marquees N/A designent un cas hors perimetre pour cette classe d'appareil. Ne pas les modifier.
A13: Exemple de saisie | B13: Ligne A01 : Mobile = OK, Tablette = OK, Desktop = KO, Anomalie = 1440x900 Safari 17.4 : la barre de progression reste a zero.
A14: En cas de KO | B14: Renseigner la colonne Anomalie : appareil exact, navigateur, version, comportement observe.
A15: Onglet Synthese | B15: Se met a jour seul. Aucune saisie, sauf la cellule jaune d'en-tete de campagne.
A17: PREREQUIS
A18: Environnement | B18: URL de preproduction ou de production, distincte du poste local.
A19: Jeu de liens | B19: Le lien de lecture (?p=<slug>) et le lien d'edition (?p=<slug>&k=<jeton>).
A20: Slug de recette | B20: Utiliser un slug dedie aux tests, jamais celui d'un parcours reel : la campagne ecrit et efface des donnees.
A21: Remise a zero | B21: Avant la campagne : decocher toutes les cases et vider tous les champs de lien sur le slug de recette.
A23: PRIORITES
A24: P1 | B24: Bloquant. Un KO interdit la mise en production.
A25: P2 | B25: Majeur. Un KO est arbitre, il ne bloque pas necessairement.

Sheet Matrice devices
A1: Matrice de couverture
A2: Chaque classe d'appareil doit etre couverte par au moins une configuration P1.
A4: Ref | B4: Classe | C4: Appareil / resolution | D4: Navigateur | E4: Systeme | F4: Prio | G4: Point d'attention
A5: D1 | B5: Mobile | C5: iPhone 13/14/15 - 390 x 844 | D5: Safari | E5: iOS 17+ | F5: P1 | G5: Reference mobile. Flou d'arriere-plan et barre d'adresse retractable.
A6: D2 | B6: Mobile | C6: Pixel / Galaxy - 412 x 915 | D6: Chrome | E6: Android 13+ | F6: P1 | G6: Reference Android. Rendu des polices et des ombres.
A7: D3 | B7: Mobile | C7: Petit ecran - 360 x 640 | D7: Chrome | E7: Android | F7: P2 | G7: Cas le plus contraint. Debordement horizontal, longueur des libelles.
A8: D4 | B8: Tablette | C8: iPad portrait - 768 x 1024 | D8: Safari | E8: iPadOS | F8: P1 | G8: Une seule colonne attendue, carte plafonnee a 660 px.
A9: D5 | B9: Tablette | C9: iPad paysage - 1024 x 768 | D9: Safari | E9: iPadOS | F9: P1 | G9: Bascule a deux colonnes. Seuil de rupture a 880 px.
A10: D6 | B10: Desktop | C10: 1280 x 800 | D10: Chrome | E10: macOS / Win | F10: P1 | G10: Configuration de reference bureau.
A11: D7 | B11: Desktop | C11: 1440 x 900 | D11: Safari | E11: macOS | F11: P1 | G11: Moteur WebKit. Prefixes -webkit- du flou d'arriere-plan.
A12: D8 | B12: Desktop | C12: 1920 x 1080 | D12: Edge | E12: Windows 11 | F12: P2 | G12: Cadre plafonne a 1140 px : verifier l'absence d'etalement.
A13: D9 | B13: Desktop | C13: 1440 x 900 | D13: Firefox | E13: Windows | F13: P2 | G13: Moteur Gecko. Rendu du flou et du grain.
A15: Classes utilisees dans l'onglet Cas de test : Mobile = D1 D2 D3 | Tablette = D4 D5 | Desktop = D6 D7 D8 D9

Sheet Cas de test
A1: Cas de test
A2: Saisir uniquement les colonnes Mobile, Tablette, Desktop et Anomalie.
A4: Ref | B4: Domaine | C4: Cas de test | D4: Preconditions | E4: Etapes | F4: Resultat attendu | G4: Prio | H4: Mobile | I4: Tablette | J4: Desktop | K4: Anomalie constatee
A5: A01 | B5: A. Chargement | C5: Ouverture du lien de lecture | D5: Slug de recette existant | E5: Ouvrir ?p=<slug> | F5: La page s'affiche : titre, sous-titre, barre de progression, six cartes. | G5: P1
A6: A02 | B6: A. Chargement | C6: Contenu issu de parcours.json | D6: - | E6: Comparer l'ecran au fichier parcours.json | F6: Chaque etape, semaine, jalon et tache correspond au fichier, dans le meme ordre. | G6: P1 | H6: N/A | I6: N/A
A7: A03 | B7: A. Chargement | C7: Etat initial conforme au serveur | D7: Progression enregistree non nulle | E7: Recharger la page | F7: Coches, liens, compteur et barre refletent l'etat stocke. | G7: P1
A8: A04 | B8: A. Chargement | C8: parcours.json illisible | D8: Renommer temporairement le fichier | E8: Recharger | F8: Message d'erreur explicite. Pas de page blanche. | G8: P2 | H8: N/A | I8: N/A
A9: A05 | B9: A. Chargement | C9: Stockage indisponible | D9: Retirer la variable d'environnement du store | E9: Recharger puis cocher une case | F9: Pastille Hors ligne. La page reste consultable et manipulable localement. | G9: P1 | H9: N/A | I9: N/A
A10: A06 | B10: A. Chargement | C10: Polices distantes bloquees | D10: Bloquer fonts.googleapis.com | E10: Recharger | F10: Texte lisible via les polices de repli. Aucun texte invisible. | G10: P2 | H10: N/A | I10: N/A
A11: B01 | B11: B. Droits d'acces | C11: Lien de lecture : cases verrouillees | D11: Lien sans jeton | E11: Cliquer sur une case | F11: Aucun changement. Les cases sont desactivees. | G11: P1
A12: B02 | B12: B. Droits d'acces | C12: Lien de lecture : pas de champ de saisie | D12: Lien sans jeton | E12: Observer la zone lien de chaque carte | F12: Aucun champ editable. Le lien depose s'affiche en consultation, sinon Aucun lien depose. | G12: P1
A13: B03 | B13: B. Droits d'acces | C13: Lien de lecture : pastille | D13: Lien sans jeton | E13: Observer le bas de l'ecran | F13: Pastille Lecture seule affichee en permanence. | G13: P2
A14: B04 | B14: B. Droits d'acces | C14: Lien d'edition : edition possible | D14: Lien avec jeton valide | E14: Cocher une case | F14: La case se coche, la pastille passe a Enregistrement puis Enregistre. | G14: P1
A15: B05 | B15: B. Droits d'acces | C15: Jeton errone : ecriture refusee | D15: Lien avec un jeton faux | E15: Cocher une case | F15: Pastille d'echec. Apres rechargement, la coche a disparu. | G15: P1 | H15: N/A | I15: N/A
A16: B06 | B16: B. Droits d'acces | C16: Ecriture forgee hors navigateur | D16: Terminal | E16: POST /api/progress?p=<slug> sans parametre k | F16: Reponse HTTP 403. Aucune donnee modifiee. | G16: P1 | H16: N/A | I16: N/A
A17: B07 | B17: B. Droits d'acces | C17: Slug invalide | D17: - | E17: Ouvrir ?p=A_B/C | F17: Reponse 400 cote API. La page ne casse pas. | G17: P2 | H17: N/A | I17: N/A
A18: C01 | B18: C. Progression | C18: Cocher une tache | D18: Lien d'edition | E18: Cocher une case | F18: Pastille verte, coche tracee, libelle attenue. | G18: P1
A19: C02 | B19: C. Progression | C19: Decocher une tache | D19: Tache cochee | E19: Decocher | F19: Retour a l'etat initial, enregistre. | G19: P1
A20: C03 | B20: C. Progression | C20: Etape completee | D20: Lien d'edition | E20: Cocher toutes les taches d'une etape | F20: Bordure et point de l'etape passent au vert, compteur incremente de 1. | G20: P1
A21: C04 | B21: C. Progression | C21: Etape decompletee | D21: Etape complete | E21: Decocher une tache | F21: L'etape s'eteint, compteur decremente de 1. | G21: P1
A22: C05 | B22: C. Progression | C22: Barre proportionnelle | D22: 3 etapes sur 6 completes | E22: Observer la barre | F22: Remplissage a la moitie exactement. | G22: P2
A23: C06 | B23: C. Progression | C23: Ambiance liee a la progression | D23: 0 puis 6 etapes completes | E23: Comparer les deux etats | F23: Le fond s'eclaircit a mesure des jalons valides. | G23: P2
A24: C07 | B24: C. Progression | C24: Persistance apres rechargement | D24: Plusieurs cases cochees | E24: Attendre 2 s puis recharger | F24: Etat identique avant et apres rechargement. | G24: P1
A25: C08 | B25: C. Progression | C25: Enregistrement groupe | D25: Onglet reseau ouvert | E25: Cocher 5 cases en moins d'une seconde | F25: Une seule requete POST, 800 ms apres le dernier clic. | G25: P2 | H25: N/A | I25: N/A
A26: D01 | B26: D. Liens de rendu | C26: URL complete | D26: Lien d'edition | E26: Coller https://figma.com/file/xxx | F26: Le bouton Ouvrir apparait. | G26: P1
A27: D02 | B27: D. Liens de rendu | C27: URL sans protocole | D27: Lien d'edition | E27: Coller figma.com/file/xxx | F27: La valeur est reconnue, https:// est ajoute a l'ouverture. | G27: P1
A28: D03 | B28: D. Liens de rendu | C28: Saisie non exploitable | D28: Lien d'edition | E28: Saisir un texte libre | F28: Le bouton Ouvrir reste masque. Aucune erreur. | G28: P2
A29: D04 | B29: D. Liens de rendu | C29: Ouverture du rendu | D29: Lien renseigne | E29: Activer Ouvrir | F29: Nouvel onglet sur la bonne adresse. | G29: P1
A30: D05 | B30: D. Liens de rendu | C30: Suppression d'un lien | D30: Lien renseigne | E30: Vider le champ puis recharger | F30: Le champ reste vide. Le lien a bien ete retire cote serveur. | G30: P1
A31: D06 | B31: D. Liens de rendu | C31: Adresse tres longue | D31: - | E31: Coller une URL de 300 caracteres | F31: Affichage tronque par points de suite. Aucun debordement de la carte. | G31: P2
A32: D07 | B32: D. Liens de rendu | C32: Protocole dangereux | D32: - | E32: Coller javascript:alert(1) | F32: Valeur rejetee, aucun bouton Ouvrir, aucune execution. | G32: P1 | H32: N/A | I32: N/A
A33: E01 | B33: E. Partage | C33: Propagation vers la vue lecture | D33: Deux appareils : edition et lecture | E33: Cocher cote edition puis attendre 45 s | F33: La vue lecture se met a jour sans intervention. | G33: P1
A34: E02 | B34: E. Partage | C34: Coherence entre deux lecteurs | D34: Deux navigateurs en lecture | E34: Comparer apres rafraichissement | F34: Etat strictement identique. | G34: P2
A35: E03 | B35: E. Partage | C35: Isolation entre parcours | D35: Deux slugs distincts | E35: Modifier l'un puis consulter l'autre | F35: Aucune contamination entre les deux parcours. | G35: P1 | H35: N/A | I35: N/A
A36: F01 | B36: F. Contenu | C36: Ajout d'une tache | D36: Progression existante | E36: Ajouter une tache avec un nouvel identifiant puis deployer | F36: Les coches existantes restent en place. La nouvelle tache est decochee. | G36: P1 | H36: N/A | I36: N/A
A37: F02 | B37: F. Contenu | C37: Suppression d'une tache | D37: Progression existante | E37: Retirer une tache puis deployer | F37: Les coches restantes sont inchangees. L'etape se recalcule correctement. | G37: P1 | H37: N/A | I37: N/A
A38: F03 | B38: F. Contenu | C38: Modification d'un libelle | D38: Progression existante | E38: Changer un texte sans toucher a l'identifiant | F38: Aucun effet sur la progression. | G38: P1 | H38: N/A | I38: N/A
A39: F04 | B39: F. Contenu | C39: Ajout d'une etape | D39: - | E39: Ajouter une etape puis deployer | F39: Le total du compteur passe de 6 a 7. La grille reste equilibree. | G39: P2 | H39: N/A | I39: N/A
A40: F05 | B40: F. Contenu | C40: Caracteres speciaux et accents | D40: - | E40: Saisir apostrophes, accents et esperluettes dans un libelle | F40: Rendu correct, aucun caractere echappe visible a l'ecran. | G40: P2 | H40: N/A | I40: N/A
A41: G01 | B41: G. Affichage | C41: Mobile portrait | D41: - | E41: Ouvrir en 390 x 844 puis 360 x 640 | F41: Une colonne. Aucun defilement horizontal. Aucun texte tronque. | G41: P1 | I41: N/A | J41: N/A
...

Sheet Synthese
A1: Synthese de campagne
A2: Calculee automatiquement. Seule la cellule jaune est a renseigner.
A4: Campagne | B4: date / version deployee / testeur
A6: Classe | B6: OK | C6: KO | D6: N/A | E6: Non teste | F6: A traiter | G6: Couverture
A7: Mobile | B7: =COUNTIF('Cas de test'!H5:H67,"OK") -> 0 | C7: =COUNTIF('Cas de test'!H5:H67,"KO") -> 0 | D7: =COUNTIF('Cas de test'!H5:H67,"N/A") -> 31 | E7: =COUNTIF('Cas de test'!H5:H67,"Non teste") -> 0 | F7: =COUNTBLANK('Cas de test'!H5:H67)+E7 -> 32 | G7: =IFERROR((B7+C7)/(63-D7),0) -> 0
A8: Tablette | B8: =COUNTIF('Cas de test'!I5:I67,"OK") -> 0 | C8: =COUNTIF('Cas de test'!I5:I67,"KO") -> 0 | D8: =COUNTIF('Cas de test'!I5:I67,"N/A") -> 31 | E8: =COUNTIF('Cas de test'!I5:I67,"Non teste") -> 0 | F8: =COUNTBLANK('Cas de test'!I5:I67)+E8 -> 32 | G8: =IFERROR((B8+C8)/(63-D8),0) -> 0
A9: Desktop | B9: =COUNTIF('Cas de test'!J5:J67,"OK") -> 0 | C9: =COUNTIF('Cas de test'!J5:J67,"KO") -> 0 | D9: =COUNTIF('Cas de test'!J5:J67,"N/A") -> 8 | E9: =COUNTIF('Cas de test'!J5:J67,"Non teste") -> 0 | F9: =COUNTBLANK('Cas de test'!J5:J67)+E9 -> 55 | G9: =IFERROR((B9+C9)/(63-D9),0) -> 0
A10: Total | B10: =SUM(B7:B9) -> 0 | C10: =SUM(C7:C9) -> 0 | D10: =SUM(D7:D9) -> 70 | E10: =SUM(E7:E9) -> 0 | F10: =SUM(F7:F9) -> 119 | G10: =IFERROR((B10+C10)/(B10+C10+F10),0) -> 0
A13: VERDICT | B13: =IF(F10>0,"Campagne incomplete",IF(C10>0,"NON CONFORME - anomalies a traiter","CONFORME - mise en production autorisee")) -> Campagne incomplete
A15: Regle : un seul KO sur un cas P1 interdit la mise en production. Les KO P2 sont arbitres au cas par cas.
